Traceback (most recent call last):
  File "/home/wpl27/.local/lib/python3.5/site-packages/tensorflow/python/framework/op_def_library.py", line 510, in _apply_op_helper
    preferred_dtype=default_dtype)
  File "/home/wpl27/.local/lib/python3.5/site-packages/tensorflow/python/framework/ops.py", line 1022, in internal_convert_to_tensor
    ret = conversion_func(value, dtype=dtype, name=name, as_ref=as_ref)
  File "/home/wpl27/.local/lib/python3.5/site-packages/tensorflow/python/framework/constant_op.py", line 233, in _constant_tensor_conversion_function
    return constant(v, dtype=dtype, name=name)
  File "/home/wpl27/.local/lib/python3.5/site-packages/tensorflow/python/framework/constant_op.py", line 212, in constant
    value, dtype=dtype, shape=shape, verify_shape=verify_shape))
  File "/home/wpl27/.local/lib/python3.5/site-packages/tensorflow/python/framework/tensor_util.py", line 401, in make_tensor_proto
    raise ValueError("None values not supported.")
ValueError: None values not supported.

During handling of the above exception, another exception occurred:

Traceback (most recent call last):
  File "/home/wpl27/.local/lib/python3.5/site-packages/tensorflow/python/framework/op_def_library.py", line 524, in _apply_op_helper
    values, as_ref=input_arg.is_ref).dtype.name
  File "/home/wpl27/.local/lib/python3.5/site-packages/tensorflow/python/framework/ops.py", line 1022, in internal_convert_to_tensor
    ret = conversion_func(value, dtype=dtype, name=name, as_ref=as_ref)
  File "/home/wpl27/.local/lib/python3.5/site-packages/tensorflow/python/framework/constant_op.py", line 233, in _constant_tensor_conversion_function
    return constant(v, dtype=dtype, name=name)
  File "/home/wpl27/.local/lib/python3.5/site-packages/tensorflow/python/framework/constant_op.py", line 212, in constant
    value, dtype=dtype, shape=shape, verify_shape=verify_shape))
  File "/home/wpl27/.local/lib/python3.5/site-packages/tensorflow/python/framework/tensor_util.py", line 401, in make_tensor_proto
    raise ValueError("None values not supported.")
ValueError: None values not supported.

During handling of the above exception, another exception occurred:

Traceback (most recent call last):
  File "./train.py", line 46, in <module>
    accum_ops = [accum_vars[i].assign_add(gv[0]) for i, gv in enumerate(gvs)]
  File "./train.py", line 46, in <listcomp>
    accum_ops = [accum_vars[i].assign_add(gv[0]) for i, gv in enumerate(gvs)]
  File "/home/wpl27/.local/lib/python3.5/site-packages/tensorflow/python/ops/variables.py", line 609, in assign_add
    return state_ops.assign_add(self._variable, delta, use_locking=use_locking)
  File "/home/wpl27/.local/lib/python3.5/site-packages/tensorflow/python/ops/state_ops.py", line 244, in assign_add
    ref, value, use_locking=use_locking, name=name)
  File "/home/wpl27/.local/lib/python3.5/site-packages/tensorflow/python/ops/gen_state_ops.py", line 101, in assign_add
    "AssignAdd", ref=ref, value=value, use_locking=use_locking, name=name)
  File "/home/wpl27/.local/lib/python3.5/site-packages/tensorflow/python/framework/op_def_library.py", line 528, in _apply_op_helper
    (input_name, err))
ValueError: Tried to convert 'value' to a tensor and failed. Error: None values not supported.
